2025-05-18 21:21:43,403 ERROR:Traceback (most recent call last):
2025-05-18 21:21:43,403 ERROR:  File "c:\Users\Admin\pythonp\src\san5\APIWEB\run.py", line 13, in <module>
2025-05-18 21:21:43,403 ERROR:from routes import routes
2025-05-18 21:21:43,403 ERROR:  File "c:\Users\Admin\pythonp\src\san5\APIWEB\routes.py", line 49, in <module>
2025-05-18 21:21:43,404 ERROR:from fm.FImport import *
2025-05-18 21:21:43,404 ERROR:  File "c:\Users\Admin\pythonp\src\san5\fm\FImport.py", line 10, in <module>
2025-05-18 21:21:43,404 ERROR:from APIFE.api import (deactivate_old_api_keys, deactivate_old_tokens,
2025-05-18 21:21:43,404 ERROR:  File "c:\Users\Admin\pythonp\src\san5\APIFE\api.py", line 38, in <module>
2025-05-18 21:21:43,404 ERROR:logging.FileHandler(log_file),
2025-05-18 21:21:43,406 ERROR:^
2025-05-18 21:21:43,406 ERROR:^
2025-05-18 21:21:43,406 ERROR:^
2025-05-18 21:21:43,406 ERROR:^
2025-05-18 21:21:43,406 ERROR:^
2025-05-18 21:21:43,406 ERROR:^
2025-05-18 21:21:43,406 ERROR:^
2025-05-18 21:21:43,407 ERROR:^
2025-05-18 21:21:43,407 ERROR:^
2025-05-18 21:21:43,407 ERROR:^
2025-05-18 21:21:43,407 ERROR:^
2025-05-18 21:21:43,407 ERROR:^
2025-05-18 21:21:43,407 ERROR:^
2025-05-18 21:21:43,407 ERROR:^
2025-05-18 21:21:43,407 ERROR:^
2025-05-18 21:21:43,407 ERROR:^
2025-05-18 21:21:43,407 ERROR:^
2025-05-18 21:21:43,408 ERROR:^
2025-05-18 21:21:43,408 ERROR:^
2025-05-18 21:21:43,408 ERROR:^
2025-05-18 21:21:43,408 ERROR:^
2025-05-18 21:21:43,408 ERROR:^
2025-05-18 21:21:43,408 ERROR:^
2025-05-18 21:21:43,408 ERROR:^
2025-05-18 21:21:43,408 ERROR:^
2025-05-18 21:21:43,408 ERROR:^
2025-05-18 21:21:43,409 ERROR:^
2025-05-18 21:21:43,409 ERROR:^
2025-05-18 21:21:43,409 ERROR:^
2025-05-18 21:21:43,409 ERROR:  File "C:\Users\Admin\AppData\Local\Programs\Python\Python312\Lib\logging\__init__.py", line 1231, in __init__
2025-05-18 21:21:43,410 ERROR:StreamHandler.__init__(self, self._open())
2025-05-18 21:21:43,410 ERROR:^
2025-05-18 21:21:43,410 ERROR:^
2025-05-18 21:21:43,410 ERROR:^
2025-05-18 21:21:43,410 ERROR:^
2025-05-18 21:21:43,410 ERROR:^
2025-05-18 21:21:43,410 ERROR:^
2025-05-18 21:21:43,411 ERROR:^
2025-05-18 21:21:43,411 ERROR:^
2025-05-18 21:21:43,411 ERROR:^
2025-05-18 21:21:43,411 ERROR:^
2025-05-18 21:21:43,411 ERROR:^
2025-05-18 21:21:43,411 ERROR:^
2025-05-18 21:21:43,411 ERROR:  File "C:\Users\Admin\AppData\Local\Programs\Python\Python312\Lib\logging\__init__.py", line 1263, in _open
2025-05-18 21:21:43,412 ERROR:return open_func(self.baseFilename, self.mode,
2025-05-18 21:21:43,412 ERROR:^
2025-05-18 21:21:43,412 ERROR:^
2025-05-18 21:21:43,412 ERROR:^
2025-05-18 21:21:43,412 ERROR:^
2025-05-18 21:21:43,413 ERROR:^
2025-05-18 21:21:43,413 ERROR:^
2025-05-18 21:21:43,413 ERROR:^
2025-05-18 21:21:43,413 ERROR:^
2025-05-18 21:21:43,413 ERROR:^
2025-05-18 21:21:43,413 ERROR:^
2025-05-18 21:21:43,413 ERROR:^
2025-05-18 21:21:43,413 ERROR:^
2025-05-18 21:21:43,413 ERROR:^
2025-05-18 21:21:43,413 ERROR:^
2025-05-18 21:21:43,413 ERROR:^
2025-05-18 21:21:43,413 ERROR:^
2025-05-18 21:21:43,413 ERROR:^
2025-05-18 21:21:43,415 ERROR:^
2025-05-18 21:21:43,415 ERROR:^
2025-05-18 21:21:43,415 ERROR:^
2025-05-18 21:21:43,415 ERROR:^
2025-05-18 21:21:43,415 ERROR:^
2025-05-18 21:21:43,415 ERROR:^
2025-05-18 21:21:43,415 ERROR:^
2025-05-18 21:21:43,415 ERROR:^
2025-05-18 21:21:43,415 ERROR:^
2025-05-18 21:21:43,415 ERROR:^
2025-05-18 21:21:43,415 ERROR:^
2025-05-18 21:21:43,415 ERROR:^
2025-05-18 21:21:43,415 ERROR:^
2025-05-18 21:21:43,415 ERROR:^
2025-05-18 21:21:43,415 ERROR:^
2025-05-18 21:21:43,415 ERROR:^
2025-05-18 21:21:43,416 ERROR:^
2025-05-18 21:21:43,416 ERROR:^
2025-05-18 21:21:43,416 ERROR:^
2025-05-18 21:21:43,416 ERROR:^
2025-05-18 21:21:43,416 ERROR:^
2025-05-18 21:21:43,416 ERROR:^
2025-05-18 21:21:43,416 ERROR:FileNotFoundError
2025-05-18 21:21:43,416 ERROR::
2025-05-18 21:21:43,416 ERROR:[Errno 2] No such file or directory: 'c:\\Users\\Admin\\pythonp\\src\\san5\\APIFE\\data\\api.log'
