2025-05-18 21:29:30,003 ERROR:Traceback (most recent call last):
2025-05-18 21:29:30,005 ERROR:  File "C:\Users\Admin\AppData\Local\Programs\Python\Python312\Lib\runpy.py", line 198, in _run_module_as_main
2025-05-18 21:29:30,005 ERROR:return _run_code(code, main_globals, None,
2025-05-18 21:29:30,007 ERROR:^
2025-05-18 21:29:30,007 ERROR:^
2025-05-18 21:29:30,007 ERROR:^
2025-05-18 21:29:30,007 ERROR:^
2025-05-18 21:29:30,007 ERROR:^
2025-05-18 21:29:30,009 ERROR:^
2025-05-18 21:29:30,009 ERROR:^
2025-05-18 21:29:30,009 ERROR:^
2025-05-18 21:29:30,009 ERROR:^
2025-05-18 21:29:30,009 ERROR:^
2025-05-18 21:29:30,009 ERROR:^
2025-05-18 21:29:30,009 ERROR:^
2025-05-18 21:29:30,009 ERROR:^
2025-05-18 21:29:30,009 ERROR:^
2025-05-18 21:29:30,009 ERROR:^
2025-05-18 21:29:30,009 ERROR:^
2025-05-18 21:29:30,009 ERROR:^
2025-05-18 21:29:30,009 ERROR:^
2025-05-18 21:29:30,015 ERROR:^
2025-05-18 21:29:30,015 ERROR:^
2025-05-18 21:29:30,015 ERROR:^
2025-05-18 21:29:30,015 ERROR:^
2025-05-18 21:29:30,017 ERROR:^
2025-05-18 21:29:30,017 ERROR:^
2025-05-18 21:29:30,019 ERROR:^
2025-05-18 21:29:30,019 ERROR:^
2025-05-18 21:29:30,019 ERROR:^
2025-05-18 21:29:30,021 ERROR:^
2025-05-18 21:29:30,021 ERROR:^
2025-05-18 21:29:30,021 ERROR:^
2025-05-18 21:29:30,021 ERROR:^
2025-05-18 21:29:30,023 ERROR:^
2025-05-18 21:29:30,023 ERROR:^
2025-05-18 21:29:30,023 ERROR:^
2025-05-18 21:29:30,023 ERROR:^
2025-05-18 21:29:30,023 ERROR:  File "C:\Users\Admin\AppData\Local\Programs\Python\Python312\Lib\runpy.py", line 88, in _run_code
2025-05-18 21:29:30,025 ERROR:exec(code, run_globals)
2025-05-18 21:29:30,025 ERROR:  File "c:\Users\Admin\.vscode\extensions\ms-python.debugpy-2025.9.2025051201-win32-x64\bundled\libs\debugpy\launcher/../..\debugpy\__main__.py", line 71, in <module>
2025-05-18 21:29:30,025 ERROR:cli.main()
2025-05-18 21:29:30,025 ERROR:  File "c:\Users\Admin\.vscode\extensions\ms-python.debugpy-2025.9.2025051201-win32-x64\bundled\libs\debugpy\launcher/../..\debugpy/..\debugpy\server\cli.py", line 501, in main
2025-05-18 21:29:30,027 ERROR:run()
2025-05-18 21:29:30,027 ERROR:  File "c:\Users\Admin\.vscode\extensions\ms-python.debugpy-2025.9.2025051201-win32-x64\bundled\libs\debugpy\launcher/../..\debugpy/..\debugpy\server\cli.py", line 351, in run_file
2025-05-18 21:29:30,027 ERROR:runpy.run_path(target, run_name="__main__")
2025-05-18 21:29:30,028 ERROR:  File "c:\Users\Admin\.vscode\extensions\ms-python.debugpy-2025.9.2025051201-win32-x64\bundled\libs\debugpy\_vendored\pydevd\_pydevd_bundle\pydevd_runpy.py", line 310, in run_path
2025-05-18 21:29:30,028 ERROR:return _run_module_code(code, init_globals, run_name, pkg_name=pkg_name, script_name=fname)
2025-05-18 21:29:30,028 ERROR:^
2025-05-18 21:29:30,028 ERROR:^
2025-05-18 21:29:30,028 ERROR:^
2025-05-18 21:29:30,028 ERROR:^
2025-05-18 21:29:30,028 ERROR:^
2025-05-18 21:29:30,028 ERROR:^
2025-05-18 21:29:30,028 ERROR:^
2025-05-18 21:29:30,033 ERROR:^
2025-05-18 21:29:30,033 ERROR:^
2025-05-18 21:29:30,033 ERROR:^
2025-05-18 21:29:30,033 ERROR:^
2025-05-18 21:29:30,033 ERROR:^
2025-05-18 21:29:30,035 ERROR:^
2025-05-18 21:29:30,035 ERROR:^
2025-05-18 21:29:30,035 ERROR:^
2025-05-18 21:29:30,035 ERROR:^
2025-05-18 21:29:30,035 ERROR:^
2025-05-18 21:29:30,037 ERROR:^
2025-05-18 21:29:30,038 ERROR:^
2025-05-18 21:29:30,038 ERROR:^
2025-05-18 21:29:30,038 ERROR:^
2025-05-18 21:29:30,038 ERROR:^
2025-05-18 21:29:30,038 ERROR:^
2025-05-18 21:29:30,038 ERROR:^
2025-05-18 21:29:30,038 ERROR:^
2025-05-18 21:29:30,041 ERROR:^
2025-05-18 21:29:30,041 ERROR:^
2025-05-18 21:29:30,042 ERROR:^
2025-05-18 21:29:30,042 ERROR:^
2025-05-18 21:29:30,042 ERROR:^
2025-05-18 21:29:30,042 ERROR:^
2025-05-18 21:29:30,042 ERROR:^
2025-05-18 21:29:30,042 ERROR:^
2025-05-18 21:29:30,044 ERROR:^
2025-05-18 21:29:30,044 ERROR:^
2025-05-18 21:29:30,044 ERROR:^
2025-05-18 21:29:30,044 ERROR:^
2025-05-18 21:29:30,044 ERROR:^
2025-05-18 21:29:30,046 ERROR:^
2025-05-18 21:29:30,046 ERROR:^
2025-05-18 21:29:30,046 ERROR:^
2025-05-18 21:29:30,046 ERROR:^
2025-05-18 21:29:30,046 ERROR:^
2025-05-18 21:29:30,048 ERROR:^
2025-05-18 21:29:30,049 ERROR:^
2025-05-18 21:29:30,049 ERROR:^
2025-05-18 21:29:30,049 ERROR:^
2025-05-18 21:29:30,049 ERROR:^
2025-05-18 21:29:30,049 ERROR:^
2025-05-18 21:29:30,051 ERROR:^
2025-05-18 21:29:30,051 ERROR:^
2025-05-18 21:29:30,051 ERROR:^
2025-05-18 21:29:30,051 ERROR:^
2025-05-18 21:29:30,052 ERROR:^
2025-05-18 21:29:30,052 ERROR:^
2025-05-18 21:29:30,052 ERROR:^
2025-05-18 21:29:30,052 ERROR:^
2025-05-18 21:29:30,052 ERROR:^
2025-05-18 21:29:30,052 ERROR:^
2025-05-18 21:29:30,052 ERROR:^
2025-05-18 21:29:30,054 ERROR:^
2025-05-18 21:29:30,054 ERROR:^
2025-05-18 21:29:30,054 ERROR:^
2025-05-18 21:29:30,054 ERROR:^
2025-05-18 21:29:30,054 ERROR:^
2025-05-18 21:29:30,054 ERROR:^
2025-05-18 21:29:30,054 ERROR:^
2025-05-18 21:29:30,054 ERROR:^
2025-05-18 21:29:30,054 ERROR:^
2025-05-18 21:29:30,054 ERROR:^
2025-05-18 21:29:30,054 ERROR:^
2025-05-18 21:29:30,054 ERROR:^
2025-05-18 21:29:30,057 ERROR:^
2025-05-18 21:29:30,057 ERROR:^
2025-05-18 21:29:30,057 ERROR:^
2025-05-18 21:29:30,057 ERROR:^
2025-05-18 21:29:30,057 ERROR:^
2025-05-18 21:29:30,059 ERROR:^
2025-05-18 21:29:30,059 ERROR:^
2025-05-18 21:29:30,059 ERROR:^
2025-05-18 21:29:30,059 ERROR:^
2025-05-18 21:29:30,059 ERROR:^
2025-05-18 21:29:30,059 ERROR:^
2025-05-18 21:29:30,059 ERROR:^
2025-05-18 21:29:30,059 ERROR:  File "c:\Users\Admin\.vscode\extensions\ms-python.debugpy-2025.9.2025051201-win32-x64\bundled\libs\debugpy\_vendored\pydevd\_pydevd_bundle\pydevd_runpy.py", line 127, in _run_module_code
2025-05-18 21:29:30,059 ERROR:_run_code(code, mod_globals, init_globals, mod_name, mod_spec, pkg_name, script_name)
2025-05-18 21:29:30,059 ERROR:  File "c:\Users\Admin\.vscode\extensions\ms-python.debugpy-2025.9.2025051201-win32-x64\bundled\libs\debugpy\_vendored\pydevd\_pydevd_bundle\pydevd_runpy.py", line 118, in _run_code
2025-05-18 21:29:30,059 ERROR:exec(code, run_globals)
2025-05-18 21:29:30,059 ERROR:  File "c:\Users\Admin\pythonp\src\san5\APIWEB\run.py", line 13, in <module>
2025-05-18 21:29:30,064 ERROR:from routes import routes
2025-05-18 21:29:30,064 ERROR:  File "c:\Users\Admin\pythonp\src\san5\APIWEB\routes.py", line 49, in <module>
2025-05-18 21:29:30,066 ERROR:from fm.FImport import *
2025-05-18 21:29:30,066 ERROR:  File "c:\Users\Admin\pythonp\src\san5\fm\FImport.py", line 10, in <module>
2025-05-18 21:29:30,067 ERROR:from APIFE.api import (deactivate_old_api_keys, deactivate_old_tokens,
2025-05-18 21:29:30,067 ERROR:  File "c:\Users\Admin\pythonp\src\san5\APIFE\api.py", line 38, in <module>
2025-05-18 21:29:30,067 ERROR:logging.FileHandler(log_file),
2025-05-18 21:29:30,068 ERROR:^
2025-05-18 21:29:30,068 ERROR:^
2025-05-18 21:29:30,068 ERROR:^
2025-05-18 21:29:30,068 ERROR:^
2025-05-18 21:29:30,068 ERROR:^
2025-05-18 21:29:30,068 ERROR:^
2025-05-18 21:29:30,068 ERROR:^
2025-05-18 21:29:30,071 ERROR:^
2025-05-18 21:29:30,071 ERROR:^
2025-05-18 21:29:30,071 ERROR:^
2025-05-18 21:29:30,071 ERROR:^
2025-05-18 21:29:30,071 ERROR:^
2025-05-18 21:29:30,071 ERROR:^
2025-05-18 21:29:30,071 ERROR:^
2025-05-18 21:29:30,071 ERROR:^
2025-05-18 21:29:30,074 ERROR:^
2025-05-18 21:29:30,074 ERROR:^
2025-05-18 21:29:30,074 ERROR:^
2025-05-18 21:29:30,074 ERROR:^
2025-05-18 21:29:30,074 ERROR:^
2025-05-18 21:29:30,076 ERROR:^
2025-05-18 21:29:30,076 ERROR:^
2025-05-18 21:29:30,076 ERROR:^
2025-05-18 21:29:30,076 ERROR:^
2025-05-18 21:29:30,076 ERROR:^
2025-05-18 21:29:30,076 ERROR:^
2025-05-18 21:29:30,076 ERROR:^
2025-05-18 21:29:30,076 ERROR:^
2025-05-18 21:29:30,076 ERROR:^
2025-05-18 21:29:30,076 ERROR:  File "C:\Users\Admin\AppData\Local\Programs\Python\Python312\Lib\logging\__init__.py", line 1231, in __init__
2025-05-18 21:29:30,080 ERROR:StreamHandler.__init__(self, self._open())
2025-05-18 21:29:30,080 ERROR:^
2025-05-18 21:29:30,080 ERROR:^
2025-05-18 21:29:30,080 ERROR:^
2025-05-18 21:29:30,081 ERROR:^
2025-05-18 21:29:30,081 ERROR:^
2025-05-18 21:29:30,081 ERROR:^
2025-05-18 21:29:30,081 ERROR:^
2025-05-18 21:29:30,081 ERROR:^
2025-05-18 21:29:30,081 ERROR:^
2025-05-18 21:29:30,081 ERROR:^
2025-05-18 21:29:30,085 ERROR:^
2025-05-18 21:29:30,085 ERROR:^
2025-05-18 21:29:30,085 ERROR:  File "C:\Users\Admin\AppData\Local\Programs\Python\Python312\Lib\logging\__init__.py", line 1263, in _open
2025-05-18 21:29:30,086 ERROR:return open_func(self.baseFilename, self.mode,
2025-05-18 21:29:30,086 ERROR:^
2025-05-18 21:29:30,086 ERROR:^
2025-05-18 21:29:30,086 ERROR:^
2025-05-18 21:29:30,088 ERROR:^
2025-05-18 21:29:30,088 ERROR:^
2025-05-18 21:29:30,088 ERROR:^
2025-05-18 21:29:30,089 ERROR:^
2025-05-18 21:29:30,089 ERROR:^
2025-05-18 21:29:30,089 ERROR:^
2025-05-18 21:29:30,089 ERROR:^
2025-05-18 21:29:30,089 ERROR:^
2025-05-18 21:29:30,089 ERROR:^
2025-05-18 21:29:30,089 ERROR:^
2025-05-18 21:29:30,089 ERROR:^
2025-05-18 21:29:30,089 ERROR:^
2025-05-18 21:29:30,089 ERROR:^
2025-05-18 21:29:30,089 ERROR:^
2025-05-18 21:29:30,089 ERROR:^
2025-05-18 21:29:30,089 ERROR:^
2025-05-18 21:29:30,089 ERROR:^
2025-05-18 21:29:30,089 ERROR:^
2025-05-18 21:29:30,089 ERROR:^
2025-05-18 21:29:30,089 ERROR:^
2025-05-18 21:29:30,089 ERROR:^
2025-05-18 21:29:30,089 ERROR:^
2025-05-18 21:29:30,089 ERROR:^
2025-05-18 21:29:30,089 ERROR:^
2025-05-18 21:29:30,089 ERROR:^
2025-05-18 21:29:30,089 ERROR:^
2025-05-18 21:29:30,089 ERROR:^
2025-05-18 21:29:30,089 ERROR:^
2025-05-18 21:29:30,089 ERROR:^
2025-05-18 21:29:30,089 ERROR:^
2025-05-18 21:29:30,089 ERROR:^
2025-05-18 21:29:30,089 ERROR:^
2025-05-18 21:29:30,098 ERROR:^
2025-05-18 21:29:30,098 ERROR:^
2025-05-18 21:29:30,098 ERROR:^
2025-05-18 21:29:30,098 ERROR:^
2025-05-18 21:29:30,098 ERROR:FileNotFoundError
2025-05-18 21:29:30,098 ERROR::
2025-05-18 21:29:30,098 ERROR:[Errno 2] No such file or directory: 'c:\\Users\\Admin\\pythonp\\src\\san5\\APIFE\\data\\api.log'
