2025-05-18 21:31:15,423 ERROR:Traceback (most recent call last):
2025-05-18 21:31:17,138 ERROR:  File "C:\Users\Admin\AppData\Local\Programs\Python\Python312\Lib\runpy.py", line 198, in _run_module_as_main
2025-05-18 21:31:18,058 ERROR:return _run_code(code, main_globals, None,
2025-05-18 21:31:21,815 ERROR:^
2025-05-18 21:31:22,431 ERROR:^
2025-05-18 21:31:22,974 ERROR:^
2025-05-18 21:31:24,088 ERROR:^
2025-05-18 21:31:25,060 ERROR:^
2025-05-18 21:31:25,688 ERROR:^
2025-05-18 21:31:26,287 ERROR:^
2025-05-18 21:31:27,694 ERROR:^
2025-05-18 21:31:27,697 ERROR:^
2025-05-18 21:31:27,697 ERROR:^
2025-05-18 21:31:27,697 ERROR:^
2025-05-18 21:31:27,697 ERROR:^
2025-05-18 21:31:27,697 ERROR:^
2025-05-18 21:31:27,697 ERROR:^
2025-05-18 21:31:27,699 ERROR:^
2025-05-18 21:31:27,699 ERROR:^
2025-05-18 21:31:27,699 ERROR:^
2025-05-18 21:31:27,699 ERROR:^
2025-05-18 21:31:27,701 ERROR:^
2025-05-18 21:31:27,701 ERROR:^
2025-05-18 21:31:27,701 ERROR:^
2025-05-18 21:31:27,702 ERROR:^
2025-05-18 21:31:27,702 ERROR:^
2025-05-18 21:31:27,702 ERROR:^
2025-05-18 21:31:27,702 ERROR:^
2025-05-18 21:31:27,702 ERROR:^
2025-05-18 21:31:27,702 ERROR:^
2025-05-18 21:31:27,704 ERROR:^
2025-05-18 21:31:27,704 ERROR:^
2025-05-18 21:31:27,704 ERROR:^
2025-05-18 21:31:27,704 ERROR:^
2025-05-18 21:31:27,704 ERROR:^
2025-05-18 21:31:27,704 ERROR:^
2025-05-18 21:31:27,704 ERROR:^
2025-05-18 21:31:27,705 ERROR:^
2025-05-18 21:31:27,705 ERROR:  File "C:\Users\Admin\AppData\Local\Programs\Python\Python312\Lib\runpy.py", line 88, in _run_code
2025-05-18 21:31:27,705 ERROR:exec(code, run_globals)
2025-05-18 21:31:27,705 ERROR:  File "c:\Users\Admin\.vscode\extensions\ms-python.debugpy-2025.9.2025051201-win32-x64\bundled\libs\debugpy\launcher/../..\debugpy\__main__.py", line 71, in <module>
2025-05-18 21:31:27,705 ERROR:cli.main()
2025-05-18 21:31:27,705 ERROR:  File "c:\Users\Admin\.vscode\extensions\ms-python.debugpy-2025.9.2025051201-win32-x64\bundled\libs\debugpy\launcher/../..\debugpy/..\debugpy\server\cli.py", line 501, in main
2025-05-18 21:31:27,708 ERROR:run()
2025-05-18 21:31:27,708 ERROR:  File "c:\Users\Admin\.vscode\extensions\ms-python.debugpy-2025.9.2025051201-win32-x64\bundled\libs\debugpy\launcher/../..\debugpy/..\debugpy\server\cli.py", line 351, in run_file
2025-05-18 21:31:27,708 ERROR:runpy.run_path(target, run_name="__main__")
2025-05-18 21:31:27,709 ERROR:  File "c:\Users\Admin\.vscode\extensions\ms-python.debugpy-2025.9.2025051201-win32-x64\bundled\libs\debugpy\_vendored\pydevd\_pydevd_bundle\pydevd_runpy.py", line 310, in run_path
2025-05-18 21:31:27,709 ERROR:return _run_module_code(code, init_globals, run_name, pkg_name=pkg_name, script_name=fname)
2025-05-18 21:31:27,710 ERROR:^
2025-05-18 21:31:27,710 ERROR:^
2025-05-18 21:31:27,710 ERROR:^
2025-05-18 21:31:27,710 ERROR:^
2025-05-18 21:31:27,710 ERROR:^
2025-05-18 21:31:27,710 ERROR:^
2025-05-18 21:31:27,710 ERROR:^
2025-05-18 21:31:27,710 ERROR:^
2025-05-18 21:31:27,710 ERROR:^
2025-05-18 21:31:27,710 ERROR:^
2025-05-18 21:31:27,710 ERROR:^
2025-05-18 21:31:27,710 ERROR:^
2025-05-18 21:31:27,714 ERROR:^
2025-05-18 21:31:27,714 ERROR:^
2025-05-18 21:31:27,714 ERROR:^
2025-05-18 21:31:27,714 ERROR:^
2025-05-18 21:31:27,714 ERROR:^
2025-05-18 21:31:27,714 ERROR:^
2025-05-18 21:31:27,714 ERROR:^
2025-05-18 21:31:27,716 ERROR:^
2025-05-18 21:31:27,716 ERROR:^
2025-05-18 21:31:27,716 ERROR:^
2025-05-18 21:31:27,716 ERROR:^
2025-05-18 21:31:27,716 ERROR:^
2025-05-18 21:31:27,716 ERROR:^
2025-05-18 21:31:27,718 ERROR:^
2025-05-18 21:31:27,718 ERROR:^
2025-05-18 21:31:27,718 ERROR:^
2025-05-18 21:31:27,718 ERROR:^
2025-05-18 21:31:27,719 ERROR:^
2025-05-18 21:31:27,719 ERROR:^
2025-05-18 21:31:27,720 ERROR:^
2025-05-18 21:31:27,720 ERROR:^
2025-05-18 21:31:27,720 ERROR:^
2025-05-18 21:31:27,720 ERROR:^
2025-05-18 21:31:27,720 ERROR:^
2025-05-18 21:31:27,720 ERROR:^
2025-05-18 21:31:27,720 ERROR:^
2025-05-18 21:31:27,720 ERROR:^
2025-05-18 21:31:27,720 ERROR:^
2025-05-18 21:31:27,720 ERROR:^
2025-05-18 21:31:27,720 ERROR:^
2025-05-18 21:31:27,720 ERROR:^
2025-05-18 21:31:27,720 ERROR:^
2025-05-18 21:31:27,720 ERROR:^
2025-05-18 21:31:27,720 ERROR:^
2025-05-18 21:31:27,720 ERROR:^
2025-05-18 21:31:27,720 ERROR:^
2025-05-18 21:31:27,724 ERROR:^
2025-05-18 21:31:27,724 ERROR:^
2025-05-18 21:31:27,724 ERROR:^
2025-05-18 21:31:27,724 ERROR:^
2025-05-18 21:31:27,725 ERROR:^
2025-05-18 21:31:27,725 ERROR:^
2025-05-18 21:31:27,725 ERROR:^
2025-05-18 21:31:27,725 ERROR:^
2025-05-18 21:31:27,727 ERROR:^
2025-05-18 21:31:27,727 ERROR:^
2025-05-18 21:31:27,727 ERROR:^
2025-05-18 21:31:27,727 ERROR:^
2025-05-18 21:31:27,727 ERROR:^
2025-05-18 21:31:27,727 ERROR:^
2025-05-18 21:31:27,727 ERROR:^
2025-05-18 21:31:27,727 ERROR:^
2025-05-18 21:31:27,727 ERROR:^
2025-05-18 21:31:27,727 ERROR:^
2025-05-18 21:31:27,727 ERROR:^
2025-05-18 21:31:27,727 ERROR:^
2025-05-18 21:31:27,727 ERROR:^
2025-05-18 21:31:27,727 ERROR:^
2025-05-18 21:31:27,727 ERROR:^
2025-05-18 21:31:27,727 ERROR:^
2025-05-18 21:31:27,727 ERROR:^
2025-05-18 21:31:27,727 ERROR:^
2025-05-18 21:31:27,727 ERROR:^
2025-05-18 21:31:27,727 ERROR:^
2025-05-18 21:31:27,727 ERROR:^
2025-05-18 21:31:27,727 ERROR:^
2025-05-18 21:31:27,727 ERROR:^
2025-05-18 21:31:27,727 ERROR:^
2025-05-18 21:31:27,727 ERROR:^
2025-05-18 21:31:27,727 ERROR:^
2025-05-18 21:31:27,727 ERROR:^
2025-05-18 21:31:27,727 ERROR:^
2025-05-18 21:31:27,727 ERROR:  File "c:\Users\Admin\.vscode\extensions\ms-python.debugpy-2025.9.2025051201-win32-x64\bundled\libs\debugpy\_vendored\pydevd\_pydevd_bundle\pydevd_runpy.py", line 127, in _run_module_code
2025-05-18 21:31:27,727 ERROR:_run_code(code, mod_globals, init_globals, mod_name, mod_spec, pkg_name, script_name)
2025-05-18 21:31:27,727 ERROR:  File "c:\Users\Admin\.vscode\extensions\ms-python.debugpy-2025.9.2025051201-win32-x64\bundled\libs\debugpy\_vendored\pydevd\_pydevd_bundle\pydevd_runpy.py", line 118, in _run_code
2025-05-18 21:31:27,727 ERROR:exec(code, run_globals)
2025-05-18 21:31:27,727 ERROR:  File "c:\Users\Admin\pythonp\src\san5\APIWEB\run.py", line 13, in <module>
2025-05-18 21:31:27,727 ERROR:from routes import routes
2025-05-18 21:31:27,727 ERROR:  File "c:\Users\Admin\pythonp\src\san5\APIWEB\routes.py", line 49, in <module>
2025-05-18 21:31:27,727 ERROR:from fm.FImport import *
2025-05-18 21:31:27,727 ERROR:  File "c:\Users\Admin\pythonp\src\san5\fm\FImport.py", line 2, in <module>
2025-05-18 21:31:27,739 ERROR:import pandas as pd
2025-05-18 21:31:27,739 ERROR:  File "C:\Users\Admin\AppData\Local\Programs\Python\Python312\Lib\site-packages\pandas\__init__.py", line 151, in <module>
2025-05-18 21:31:27,756 ERROR:from pandas import api, arrays, errors, io, plotting, tseries
2025-05-18 21:31:27,756 ERROR:  File "C:\Users\Admin\AppData\Local\Programs\Python\Python312\Lib\site-packages\pandas\api\__init__.py", line 2, in <module>
2025-05-18 21:31:27,766 ERROR:from pandas.api import (
2025-05-18 21:31:27,767 ERROR:  File "C:\Users\Admin\AppData\Local\Programs\Python\Python312\Lib\site-packages\pandas\api\interchange\__init__.py", line 5, in <module>
2025-05-18 21:31:27,774 ERROR:from pandas.core.interchange.dataframe_protocol import DataFrame
2025-05-18 21:31:27,778 ERROR:  File "C:\Users\Admin\AppData\Local\Programs\Python\Python312\Lib\site-packages\pandas\core\interchange\dataframe_protocol.py", line 25, in <module>
2025-05-18 21:31:27,791 ERROR:class DlpackDeviceType(enum.IntEnum):
2025-05-18 21:31:27,791 ERROR:  File "C:\Users\Admin\AppData\Local\Programs\Python\Python312\Lib\enum.py", line 593, in __new__
2025-05-18 21:31:27,812 ERROR:raise exc.with_traceback(tb)
2025-05-18 21:31:27,812 ERROR:  File "C:\Users\Admin\AppData\Local\Programs\Python\Python312\Lib\enum.py", line 583, in __new__
2025-05-18 21:31:27,812 ERROR:enum_class = super().__new__(metacls, cls, bases, classdict, **kwds)
2025-05-18 21:31:27,812 ERROR:^
2025-05-18 21:31:27,815 ERROR:^
2025-05-18 21:31:27,815 ERROR:^
2025-05-18 21:31:27,815 ERROR:^
2025-05-18 21:31:27,816 ERROR:^
2025-05-18 21:31:27,816 ERROR:^
2025-05-18 21:31:27,816 ERROR:^
2025-05-18 21:31:27,816 ERROR:^
2025-05-18 21:31:27,816 ERROR:^
2025-05-18 21:31:27,816 ERROR:^
2025-05-18 21:31:27,816 ERROR:^
2025-05-18 21:31:27,816 ERROR:^
2025-05-18 21:31:27,816 ERROR:^
2025-05-18 21:31:27,818 ERROR:^
2025-05-18 21:31:27,818 ERROR:^
2025-05-18 21:31:27,818 ERROR:^
2025-05-18 21:31:27,818 ERROR:^
2025-05-18 21:31:27,818 ERROR:^
2025-05-18 21:31:27,820 ERROR:^
2025-05-18 21:31:27,820 ERROR:^
2025-05-18 21:31:27,820 ERROR:^
2025-05-18 21:31:27,820 ERROR:^
2025-05-18 21:31:27,820 ERROR:^
2025-05-18 21:31:27,820 ERROR:^
2025-05-18 21:31:27,820 ERROR:^
2025-05-18 21:31:27,820 ERROR:^
2025-05-18 21:31:27,820 ERROR:^
2025-05-18 21:31:27,820 ERROR:^
2025-05-18 21:31:27,820 ERROR:^
2025-05-18 21:31:27,820 ERROR:^
2025-05-18 21:31:27,820 ERROR:^
2025-05-18 21:31:27,820 ERROR:^
2025-05-18 21:31:27,820 ERROR:^
2025-05-18 21:31:27,824 ERROR:^
2025-05-18 21:31:27,824 ERROR:^
2025-05-18 21:31:27,824 ERROR:^
2025-05-18 21:31:27,824 ERROR:^
2025-05-18 21:31:27,824 ERROR:^
2025-05-18 21:31:27,826 ERROR:^
2025-05-18 21:31:27,826 ERROR:^
2025-05-18 21:31:27,826 ERROR:^
2025-05-18 21:31:27,826 ERROR:^
2025-05-18 21:31:27,826 ERROR:^
2025-05-18 21:31:27,826 ERROR:^
2025-05-18 21:31:27,827 ERROR:^
2025-05-18 21:31:27,827 ERROR:^
2025-05-18 21:31:27,827 ERROR:^
2025-05-18 21:31:27,827 ERROR:^
2025-05-18 21:31:27,827 ERROR:^
2025-05-18 21:31:27,827 ERROR:^
2025-05-18 21:31:27,827 ERROR:^
2025-05-18 21:31:27,827 ERROR:^
2025-05-18 21:31:27,827 ERROR:^
2025-05-18 21:31:27,827 ERROR:^
2025-05-18 21:31:27,829 ERROR:^
2025-05-18 21:31:27,829 ERROR:  File "C:\Users\Admin\AppData\Local\Programs\Python\Python312\Lib\enum.py", line 266, in __set_name__
2025-05-18 21:31:27,829 ERROR:enum_member = enum_class._new_member_(enum_class, *args)
2025-05-18 21:31:27,829 ERROR:^
2025-05-18 21:31:27,829 ERROR:^
2025-05-18 21:31:27,829 ERROR:^
2025-05-18 21:31:27,829 ERROR:^
2025-05-18 21:31:27,829 ERROR:^
2025-05-18 21:31:27,829 ERROR:^
2025-05-18 21:31:27,829 ERROR:^
2025-05-18 21:31:27,829 ERROR:^
2025-05-18 21:31:27,829 ERROR:^
2025-05-18 21:31:27,829 ERROR:^
2025-05-18 21:31:27,829 ERROR:^
2025-05-18 21:31:27,829 ERROR:^
2025-05-18 21:31:27,829 ERROR:^
2025-05-18 21:31:27,834 ERROR:^
2025-05-18 21:31:27,834 ERROR:^
2025-05-18 21:31:27,834 ERROR:^
2025-05-18 21:31:27,834 ERROR:^
2025-05-18 21:31:27,834 ERROR:^
2025-05-18 21:31:27,834 ERROR:^
2025-05-18 21:31:27,834 ERROR:^
2025-05-18 21:31:27,834 ERROR:^
2025-05-18 21:31:27,834 ERROR:^
2025-05-18 21:31:27,834 ERROR:^
2025-05-18 21:31:27,834 ERROR:^
2025-05-18 21:31:27,834 ERROR:^
2025-05-18 21:31:27,834 ERROR:^
2025-05-18 21:31:27,834 ERROR:^
2025-05-18 21:31:27,834 ERROR:^
2025-05-18 21:31:27,834 ERROR:^
2025-05-18 21:31:27,838 ERROR:^
2025-05-18 21:31:27,838 ERROR:^
2025-05-18 21:31:27,838 ERROR:^
2025-05-18 21:31:27,838 ERROR:^
2025-05-18 21:31:27,838 ERROR:^
2025-05-18 21:31:27,838 ERROR:^
2025-05-18 21:31:27,838 ERROR:^
2025-05-18 21:31:27,838 ERROR:^
2025-05-18 21:31:27,838 ERROR:^
2025-05-18 21:31:27,838 ERROR:^
2025-05-18 21:31:27,838 ERROR:^
2025-05-18 21:31:27,838 ERROR:^
2025-05-18 21:31:27,838 ERROR:^
2025-05-18 21:31:27,842 ERROR:TypeError
2025-05-18 21:31:27,842 ERROR::
2025-05-18 21:31:27,842 ERROR:int() argument must be a string, a bytes-like object or a real number, not 'dict'
